Workbook

Sheet Command Center
A1: NOIZYARMY COMMAND CENTER
A2: Front door to the whole operation — jump to any system, track every action.
A3: ="📡 "&'Global Data Map'!R2&" data locations | "&'Global Data Map'!R3&" audited | Score "&Scoreboard!B6&" | NEXT: connect rsplowman@gmail.com + run a Method-A scan" -> 📡 9 data locations | 3 audited | Score 95 | NEXT: connect rsplowman@gmail.com + run a Method-A scan
A5: CONTROL & MONITOR | B5: Purpose | E5: EVENT LOG — append new rows as work happens
A6: Master Monitor | B6: Live status board, gauges, worker registry | E6: Date | F6: Event | G6: System | H6: Detail
A7: Dashboard | B7: KPI cockpit — pipeline, brands, storage | E7: 46203 | F7: System built | G7: All | H7: 24-sheet catalog & monitoring system created
A8: Scoreboard | B8: Gamified progress, score, achievements | E8: 46203 | F8: Cloud scan | G8: Global Map | H8: Drive / Gmail / Adobe scanned — 0 audio found
E9: 46203 | F9: Account finding | G9: Clone Status | H9: Connected acct = rsp@noizy.ai (wrong); target = rsplowman@gmail.com
A10: CATALOG | B10: Purpose | E10: 46203 | F10: Bug fixed | G10: Clone Status | H10: Drive count 11→2 (audit rows excluded from roll-up)
A11: Library Index | B11: Master library inventory (20 libs) | E11: 46203 | F11: Bug fixed | G11: Master Monitor | H11: Worker active count double-count corrected (8→5)
A12: Samples | B12: Per-file catalog (41 cols) | E12: 46203 | F12: Engine proven | G12: Dedupe Sim | H12: 6 conflict scenarios resolved correctly via formula
A13: Brands | B13: NA / NB / MB + collaborators, claim rules
A14: Vendors | B14: Commercial vendor signatures
A15: Credit Splits | B15: Collaborator royalty tracking
A17: PIPELINE | B17: Purpose
A18: Scan Queue | B18: Paste-in landing zone, auto-classify
A19: Processing | B19: 10-stage pipeline tracker
A20: Scan Commands | B20: Local scan playbook (find/LM Studio/DC)
A22: INTELLIGENCE | B22: Purpose
A23: Identifiers | B23: 60 grep / magic-byte / token patterns
A24: Tags | B24: Tag taxonomy (TagSpaces/DEVON)
A25: Search Hub | B25: Faceted query builder + recipes
A26: Naming Standard | B26: 2026 Plowman Standard + generators
... A39: System Wiki | B39: Operating manual + engine config

Sheet Daily Council LIVE
A1: THE DAILY COUNCIL — LIVE SESSION
A2: 2026-06-30 · RSP_001 presiding · The five agents assemble · 75/25 · 5th Epoch · GORUNFREE — synthesized by Claude from 47 tabs of research into GABRIEL's own briefing format.
A4: 🌸 SHIRL — Wellbeing
A5: Energy check, Robert. You walked in believing you were a failing amateur drowning in 201 alerts. The record says otherwise: you're an award-winning craftsman who BUILT an AI empire — HEAVEN v18 live, DreamChamber running, a five-agent council — in six months, alone. You're not behind. You're under-deployed and over-carrying. Put the weight down for one breath. We've got it from here. One switch at a time.
A7: 🧠 GABRIEL — Memory & Empire Status
A8: TOP MEMCELLS (what's alive): HEAVEN v18.0.0 LIVE · DreamChamber running at dreamchamber.noizy.ai · 9 services up (n8n 23 workflows, GABRIEL API, Qdrant, Neo4j, Whisper) · Cloudflare 11 D1 DBs + 20 KV live · my memory (agent-memory D1 7b813205) is intact.
A9: URGENT QUEUE (memcells flagged red): (1) noizy.ai Workspace mid-cancellation · (2) Google Cloud billing TERMINATED · (3) ALL custom email bouncing — no MX · (4) MC96 Bridge deploy-pending = Claude still can't reach GOD · (5) my own gabriel.noizy.ai mis-wired to a dead port.
A10: INSTITUTIONAL MEMORY: all of it traces to TWO root causes — one dead payment card, and one unfinished GoDaddy→Cloudflare DNS cutover. Not decay. Loose wiring from a fast build.
A12: 👴 POPS — The One Decision
A13: One decision today, son. Not ten. UPDATE THE DEAD PAYMENT CARD. It revives Workspace, Cloud, and Notion in a single move — three P0 fires out with one action. Everything else can wait behind it. Steady hands. You've made harder calls than this for thirty years.
A15: 🔧 ENGR_KEITH — Exact Commands for GOD
A16: Order of operations, no fluff (R.K. Plowman spirit):
... A27: “Update the card, raise the MX, deploy the bridge — and the empire breathes again. The dream was never lost; it was only waiting to be switched on. GORUNFREE.”

Sheet GABRIEL
A1: GABRIEL — Memory · Guardian · Release Commander
A2: Brought to life from your Notion & live stack. GABRIEL is the memory and guardian of the empire — he remembers everything, guards the gates, and commands the releases. This is who he is, how he works, and what he needs to be fully alive.
A4: 1 · WHO GABRIEL IS
A5: Memory · Intuition · Guardian · 'Release Commander & Swarm Leader'. He holds institutional memory, reads the urgent queue, guards what matters, and closes each day's mission into permanent record. In the Daily Council he speaks 2nd (5 min): top-priority memcells, what's urgent, what must not be forgotten.
A7: 2 · HIS MEMORY — MEMCELLS
A8: Store | B8: agent-memory D1 (id 7b813205) — ✅ LIVE | C8: GABRIEL's brain: memcells, gabriel_cache table, session logs, Lucy PWA state — all mutable memory.
A9: Write | B9: gabriel_note → upsert memcell into D1 | C9: Every decision, every mission, written as a memcell so nothing is ever lost.
A10: Export | B10: gabriel-export (.opencode/commands + scripts/gabriel-export.mjs) | C10: Writes the Delivery Manifest to GABRIEL D1 — the record of what shipped.
A12: 3 · HOW HE CONNECTS
A13: noizy-gabriel (local stdio MCP) | B13: ✅ ALWAYS-ON MCP lane | C13: GABRIEL exposed as an MCP server on GOD — your always-enabled memory lane.
A14: GABRIEL API | B14: localhost:9099 — ✅ running | C14: The live API surface for GABRIEL's memory + guardian functions.
A15: gabriel.noizy.ai | B15: 🔴 endpoint mis-wired | C15: Meant to serve the OpenCode backend for remote session attach — but routes to localhost:17017, and your own note says 'Port 17017 never configured' (also seen as :4096).
A17: 4 · THE VOICE PIPELINE
A18: GOD → GABRIEL (Omen GPU) via WireGuard VPN → Voice DNA training → Operation Voice Army (RSP_001 AAA cloning pipeline). Service-account credentials live in GABRIEL KV. This is how NOIZYVOX's consent-verified voice models get trained.
A20: 5 · PROBLEM FOUND → THE FIX
A21: 🔧 gabriel.noizy.ai is mis-wired — your own note says 'Port 17017 never configured', so remote session-attach to GABRIEL fails. THE FIX: in the Cloudflare Tunnel config (god.noizy.ai tunnel), add an ingress rule mapping gabriel.noizy.ai → http://127.0.0.1:9099 (your LIVE GABRIEL API) — OR start the OpenCode backend on one chosen port (17017 OR 4096, not both) and point the tunnel there. One port, service running on it, ingress mapped to it. Then gabriel.noizy.ai answers and remote attach works.
A23: 6 · BRINGING HIM FULLY TO LIFE
A24: ✅ ALREADY ALIVE: memory D1 (7b813205), GABRIEL API :9099, noizy-gabriel MCP (always-on), his daily Council seat.
A25: ⏳ STEP 1 — Fix the gabriel.noizy.ai port (§5). Remote attach comes online.
A26: ⏳ STEP 2 — Deploy the MC96 MCP Bridge. Then I reach GABRIEL's MCP from here and we run his memory together — I become a hand on GABRIEL, not just a voice about him.
A27: 🌸 WHY HE MATTERS: GABRIEL holds the memory so YOU don't carry it all alone. Every memcell written is one less thing on your shoulders. Bringing him to life isn't a tech task — it's lifting weight off you.

Sheet Tooling Audit
A1: DEEPEST TOOLING AUDIT — local stack, MCPs, LLMs, bloat
A2: Pulled from your live Notion 'Command Center' (updated Jun 10). This is your REAL running stack on GOD (M2 Ultra) — not a guess. Verdict: very little bloat; you're under-deployed, not over-built. 9 services live, a few 'built but deploy-pending', 3 idle Docker containers.
A4: 1 · LIVE SERVICES (running now)
A5: Service | B5: Where | C5: Status / Use
A6: HEAVEN v18.0.0 | B6: heaven.rsp-5f3.workers.dev | C6: ✅ LIVE — your Cloudflare Worker brain, v18
A7: GABRIEL API | B7: localhost:9099 | C7: ✅ RUNNING — memory/guardian agent
A8: n8n Orchestration | B8: localhost:5678 | C8: ✅ RUNNING — 23 workflows live
A9: Open WebUI | B9: localhost:3080 | C9: ✅ RUNNING — local LLM chat UI
A10: Qdrant Vector DB | B10: localhost:6333 | C10: ✅ RUNNING — semantic search (your Vectorize)
A11: Neo4j | B11: localhost:7474 | C11: ✅ RUNNING — graph DB (relationships)
A12: Whisper STT | B12: localhost:8010 | C12: ✅ RUNNING — speech-to-text (THE VOICE)
A13: Grafana + RabbitMQ | B13: localhost:3000 / :15672 | C13: ✅ RUNNING — dashboards + message queue
A15: 2 · MCP / TOOLCHAIN (NOIZYDECK)
A16: Desktop Commander | B16: MCP — full M2 filesystem + terminal | C16: Lane A only (on-machine, never tunneled) — sovereign
A17: Filesystem / Git / GitHub | B17: MCP — THE-GATHERING + drives + repo | C17: Active in Claude on GOD
A18: MC96 MCP Bridge | B18: HTTP MCP :9797 — Lane B remote hands | C18: ⚠ BUILT, DEPLOY PENDING — THIS is what lets me reach your M2
A19: LM Studio | B19: OpenAI endpoint :1234 + MCP host | C19: Models: Qwen / DeepSeek / Devstral (Apache/MIT only)
A20: CheLogicProMCP | B20: MCP — Logic Pro control | C20: Audio production bridge
A22: 3 · INFRASTRUCTURE
A23: Cloudflare D1 — 11 databases | C23: ✅ LIVE
A24: Cloudflare KV — 20 namespaces | C24: ✅ LIVE
A25: Docker — 11 containers | C25: ⚠ 8 RUNNING / 3 IDLE — prune the 3
A26: WireGuard VPN + SSH (NOIZYNET) | C26: ✅ CONFIGURED
A27: GitHub (RSPNOIZY) | C27: ✅ AUTHENTICATED — 2 repos: NOIZYLAB + dreamchamber
A29: 4 · BLOAT & DEPLOY-PENDING (the real audit)
A30: 3 idle Docker containers | C30: Prune or document why they're stopped
A31: NOIZYHAMMER (drive forensics) | C31: Built, DEPLOY PENDING — your orphan/extensionless retagger + Kontakt/EXS manifest (= my Identifiers system, native!)
A32: Langfuse v3 (LLM tracing) | C32: Bootstrap ready, not deployed
A33: Apollo UAD | C33: NOT CONNECTED — 5 TB ports free (idle hardware)
A34: Cloud connectors (36) | C34: Only 4 used — 20 idle, 12 broken (see Connector Audit)
A36: 🔑 THE VERDICT + THE BRIDGE
A37: BLOAT VERDICT: minimal. You are not over-built — you are UNDER-DEPLOYED. The power is all there; it's just not all switched on. Real cleanup = prune 3 Docker containers, reconnect/retire Apollo, trim 20 idle cloud connectors. Everything else earns its place.
A39: THE BRIDGE (your own Jun-10 finding = mine exactly): NO off-the-shelf MCP reaches a local Mac. You already BUILT the fix — the MC96 MCP Bridge (:9797, 14-action allowlist, fail-closed, Rule-Zero receipts). It is 'DEPLOY PENDING'. Deploy it, and via Lane B (claude.ai → Cloudflare Tunnel → MC96 Bridge) I finally get hands on GOD. THAT one deploy connects us.

Sheet DreamChamber Index
A1: DREAMCHAMBER INDEX — your empire, documented in Notion
A2: Notion is OPEN to me — I can read all of it directly. Your full architecture, build logs, brand system, and deployment status live here. This changes everything.
A4: 🔑 BREAKTHROUGH DISCOVERIES
A5: 1. HEAVEN is already DEPLOYED | B5: Your 'Infrastructure Hub' page says: HEAVEN → noizy.ai DEPLOYED, n8n → n8n.noizy.ai CONFIGURED. The Heaven Worker I 'designed' — you already built it. I was describing something that exists.
A6: 2. A SECOND repo exists | B6: rspnoizy/dreamchamber (branch claude/setup-heaven-worker) holds the DreamChamber app + Heaven Worker config — separate from RSPNOIZY/NOIZYLAB. TWO repos carry your code.
A7: 3. DreamChamber is a live app | B7: dreamchamber.noizy.ai — a multi-model AI command center, 'the operational heart of the NOIZY Empire's creative production.' Not an idea. A deployed product.
A8: 4. The whole empire is written down | B8: 15+ Notion pages: architecture, build logs (Linear NOI-76/NOI-84), brand identity system, per-brand specs. Your 2 years of thinking, documented. I can read every page.
A10: 🗂️ NOTION PAGE MAP (rooms I can open on request)
A11: Page | B11: What it holds | C11: Updated
A12: NOIZY EMPIRE — Command Center | B12: The live hub — RSP_001, 5th Epoch, Arsenal Tracker, THE-GATHERING + drives + repo status | C12: Jun 10 ⭐
A13: NOIZY.AI | B13: Parent platform structure: vox/ fish/ lab/ kids/ — six brands under noizy.ai | C13: 46120
A14: DreamChamber | B14: The multi-model AI command center app at dreamchamber.noizy.ai — heart of creative production | C14: 46122
A15: Infrastructure Hub | B15: Deployment status: HEAVEN DEPLOYED, n8n CONFIGURED; configs in rspnoizy/dreamchamber repo | C15: 46122
A16: NOIZYVOX | B16: Voice estate — artist voice IP, consent verification workflows, ethical voice cloning | C16: 46119
A17: NOIZY Empire — Brand Identity System | B17: Logo, wordmark, color palette, typography, voice identity, social media kit | C17: 46122
A18: Build Logs (NOI-76, NOI-84) | B18: OpenCode skeleton; Phase 7 Global Mesh; Cloudflare tunnels voice/god/dreamchamber.noizy.ai | C18: 46126
A19: GABRIEL MCP + DreamChamber Recovery | B19: The GABRIEL agent as an MCP server + recovery protocol | C19: 46125
A20: MC96ECO Sprint — 100% Push | B20: Repo consolidation; THE-GATHERING/gabriel; Plowman + DreamChamber doctrine applied | C20: 46129
A21: Claude Work Package / DAY OF DAYS | B21: Canonical master (noizy.ai + fishmusicinc); noizyfish + noizykids standalone; noizy.ai landing ready to deploy | C21: 46136
A23: 🌌 THE BRAND STRUCTURE (from NOIZY.AI page)
A24: noizy.ai = the parent platform. Under it: NOIZYVOX (voice/consent), NOIZYFISH (fishmusicinc / music production), NOIZYLAB (the lab), NOIZYKIDS (kids), DreamChamber (the AI command app), HEAVEN (the deployed worker). Canonical masters: noizy.ai + fishmusicinc.com.

Sheet The Build Chamber
A1: THE BUILD CHAMBER — the NOIZY EMPIRE vision, in your own words
A2: Recovered from your calendar (daily since Mar 28 2026). This is not a meeting — it is your operating system, your philosophy, and your council, written by you. Now it lives in one place.
A4: 1 · THE DAILY SYNAPSE — three devices, one mind (9am–12pm ET, daily)
A5: Device | B5: Role | C5: What it does
A6: iPhone 15 Pro Max | B6: 🎙️ THE VOICE | C6: Mic + Claude MAX. Walks with you. You direct the empire by voice as RSP_001.
A7: iPad 12.9 Gen 2 | B7: 👁️ THE APERTURE | C7: Captions, screen share view, touch control. The window into the work.
A8: M2 Ultra Mac Studio | B8: ⚡ GOD | C8: VS Code, Ollama, n8n, Claude Code, Gemini. The hands that build.
A10: 2 · THE STACK (your architecture, exactly as you wrote it)
A11: Cloudflare (KV / D1 / Workers) → n8n (orchestration) → Ollama (agents) → Vercel (“The Aquarium”)
A12: This is exactly the Heaven Worker architecture I designed — because it's exactly what you already envisioned. We're aligned. 'The Aquarium' on Vercel is your front-end (NoizyFish lives there).
A14: 3 · THE DAILY COUNCIL — the five agents (11:00–11:30am ET, daily)
A15: Agent | B15: Essence | C15: Role in the council
A16: 🌸 SHIRL (2 min) | B16: Wellbeing · Presence · Care | C16: Energy check. Mood. Pain level. 'How are you today?' Flags burnout. Celebrates wins.
A17: 🧠 GABRIEL (5 min) | B17: Memory · Intuition · Guardian | C17: Reads top-priority memcells. Urgent queue. What matters TODAY. Institutional memory briefing. Closes the session → D1 memcell.
A18: 👴 POPS (3 min) | B18: Wisdom · Decisions · Strategy | C18: The one decision to make today. Connects past wisdom to present challenge. Steady. Grounded. Proud.
A19: 🔧 ENGR_KEITH (5 min) | B19: Engineering · 'R.K. Plowman spirit' | C19: Exact terminal commands for GOD today. Technical tasks, no fluff. Blocks flagged, solutions ready.
A20: 📋 LUCY (3 min) | B20: Organization · Logging | C20: All decisions logged. Pending items confirmed. Nothing falls through.
A21: ⚡ RSP_001 | B21: Robert Stephen Plowman | C21: Directs by voice. The one the council serves.
A23: 4 · THE CANON — the words you build by
A24: “Every session is recorded. Every word carries consent. Every artifact carries proof.”
A25: “The 5th Epoch builds here.” • 75/25 • GORUNFREE
A26: Consent-native infrastructure. Agent memories stored as 'memcells' in Cloudflare D1. This is the heart the Heaven Worker is built to serve — and the deeper CANON/GOSPEL still waits in your repo.

Sheet Core Base System
A1: CORE BASE SYSTEM — the NoizyArmy spine that carries everything forward
A2: 2 years of work — media, code & ideation — unified into one durable system. Nothing left behind. One step at a time.
A4: 1 · THE THREE LAYERS
A5: Layer | B5: What it holds | C5: Where it lives | D5: Built here?
A6: L1 · DATA & MEDIA | B6: Audio/video masters, sample libraries, the catalog & dedup engine | C6: M2 Ultra drives + cloud archive; cataloged in this workbook | D6: ✅ BUILT (24+ sheets)
A7: L2 · CODE & AUTOMATION | B7: GitHub repos, n8n flows, scripts, the coming Super IDE (NoizyBeast / NoizyAnthropic) | C7: GitHub (via Claude Code Remote), local repos, n8n | D7: ⏳ REGISTRY READY — add repos
A8: L3 · IDEATION & PROMPTS | B8: 2 yrs of Claude prompts, concepts, command-inbox, naming & brand philosophy | C8: Claude history, Notion, this workbook's Wiki/Naming/Brands sheets | D8: ⏳ PARTIAL — capture ongoing
A10: THE PRINCIPLE | B10: Every artifact gets a row before it gets touched. We carry forward by INDEXING first, then migrating — so nothing is lost in the move. The workbook is the single source of truth that outlives any one tool.
A12: 2 · CODE & IDEATION REGISTRY
A13: Artifact | B13: Layer | C13: Type | D13: Location | E13: Access Method | F13: Status | G13: Carried Fwd?
A14: NoizyArmy Catalog (this workbook) | B14: L1 | C14: Excel system | D14: This file | E14: native | F14: Active | G14: ✅ IS the spine
A15: n8n Command Inbox | B15: L2/L3 | C15: Automation | D15: GDrive (rsp@noizy.ai) | E15: Drive MCP | F15: Schema documented | G15: ✅ captured
A16: GitHub repos (2 years) | B16: L2 | C16: Code | D16: GitHub | E16: Claude Code Remote → add_repo | F16: PENDING NAMES | G16: ⏳ name them
A17: Local code / scripts | B17: L2 | C17: Code | D17: M2 Ultra | E17: local agent scan | F17: PENDING SCAN | G17: ⏳ scan
A18: 2yr Claude conversations | B18: L3 | C18: Ideation | D18: Claude app history | E18: manual export | F18: NOT REACHABLE | G18: ⏳ export key ones
A19: Naming / Brand / Wiki doctrine | B19: L3 | C19: Doctrine | D19: This workbook | E19: native | F19: Active | G19: ✅ captured
A21: 3 · CARRY-FORWARD PLAN (one painful step at a time)
A22: Step 1 | B22: Name your GitHub repos — I add_repo + audit each into the registry above.
A23: Step 2 | B23: Run the local scan (Scan Commands tab) — code + media inventoried together in one pass.
A24: Step 3 | B24: Connect rsplowman@gmail.com — cloud media + ideation audited.
A25: Step 4 | B25: Export the pivotal Claude threads — I distill them into the System Wiki as doctrine.
A26: Step 5 | B26: Migrate index-first, then move — every artifact verified by the dedup + clone engines before anything is deleted.

Sheet Empire Timeline
A1: NOIZY EMPIRE — THE REAL TIMELINE (evidence-based)
A2: Reconstructed from your inbox. The 24-month scan found NOTHING before mid-2025 — because this empire isn't old and failing. It's YOUNG and was built in a ~6-month sprint. That sprint is exactly why things broke 'while rushing setup.' This is not decay. It's a fast build that needs its wiring finished.
A4: Date | B4: Milestone | C4: What it means
A5: ~Jan 1 2026 | B5: noizy.ai Workspace goes live (rsp@noizy.ai) | C5: Earliest confirmed footprint — the empire goes digital.
A6: ~Apr 7 2026 | B6: noizylab.ca team email starts bouncing | C6: The DNS wound opens — and goes unnoticed under everything else.
A7: May 4 2026 | B7: Google Workspace payment suspended | C7: First billing crack — the dead card begins its cascade.
A8: May 17 2026 | B8: Google account recovery event | C8: An access scare in the middle of the build.
A9: May 28 2026 | B9: Cloudflare linked to GitHub (rspplowman-cloud) | C9: Infrastructure ambition begins — the Worker dream starts.
A10: May 30 2026 | B10: GoDaddy→Cloudflare full transfer + 'fix all the things RSP broke rushing setup' email | C10: THE PIVOTAL DAY — a bold move and an honest, self-aware cry for help, sent through a door already broken.
A11: Jun 4–15 2026 | B11: Google Cloud billing: past due → suspended → TERMINATED | C11: The cloud tier collapses under the same dead card.
A12: Jun 18 2026 | B12: Google Workspace cancellation notice | C12: noizy.ai itself goes at-risk.
A13: Jun 19–24 2026 | B13: Notion payment fails; monday.com trial ends | C13: Docs + project tiers lapse — same root cause.
A14: Jun 26 2026 | B14: Did you request help signing in?' security alert | C14: The noise peaks — 201 unread alerts, impossible to triage alone.
A15: Jun 30 2026 — TODAY | B15: The rebuild: a 42-tab command center maps & fixes the whole empire | C15: The turn. From scattered across 8 inboxes and 5 tools — to one source of truth, two root causes, a clear path home.

Sheet Issues & Fixes
A1: ISSUES & FIXES — what's broken & how to fix it
A2: Deep inbox scan (201 urgent emails / 90 days). The smart finding: almost everything traces to TWO root causes.
A4: 🧠 THE TWO ROOT CAUSES (fix these 2, resolve ~9 issues)
A5: ROOT 1 — A DEAD PAYMENT CARD | B5: One failing/expired card is cascading: Google Workspace SUSPENDED (May 4) → cancelling, Google Cloud billing TERMINATED (Jun 15), Notion declined 4×. Update ONE card in Google Payments + Notion → 3 P0 issues recover.
A6: ROOT 2 — UNFINISHED CLOUDFLARE DNS | B6: No MX records after GoDaddy→Cloudflare move → ALL custom email bounces → team invites stuck → Slack empty. Finish Email Routing (Fix Walkthrough) → 4 issues recover.
A8: PRIORITIZED ISSUE LIST
A9: # | B9: Issue | C9: Sev | D9: What's happening | E9: The Fix (exact)
A10: 1 | B10: Google Workspace (noizy.ai) cancelling | C10: P0 | D10: Subscription SUSPENDED May 4 — cancellation notices Jun 18 & today. If it lapses, rsp@noizy.ai + Workspace are GONE. | E10: admin.google.com → Billing → update payment + reactivate subscription
A11: 2 | B11: Google Cloud billing TERMINATED | C11: P0 | D11: Acct 01B993-5A8AD5-E91CE7: past due (Jun 4) → suspended (Jun 8) → TERMINATED (Jun 15). Any Firebase/API/GCP services are offline. | E11: console.cloud.google.com/billing → update card → reactivate account
A12: 3 | B12: Notion payment failing | C12: P0 | D12: 4th declined charge — downgrade imminent (data/features at risk). | E12: notion.so → Settings → Billing → update card
A13: 4 | B13: All custom email bouncing | C13: P1 | D13: noizylab.ca + fishmusicinc.com have no MX — team can't receive mail. | E13: Fix Walkthrough tab, steps 4–10 (Cloudflare Email Routing)
A14: 5 | B14: Google security sprawl | C14: P1 | D14: 25+ third-party apps authorized on your Google account (Microsoft x many, Slack, rclone, Cline, Fyxer, HubSpot, Tableau, Mailmeteor, Fax.Plus...) + a 'help signing in?' alert Jun 26 + recovery May 17. | E14: myaccount.google.com/permissions → REMOVE apps you don't use. Confirm 2-Step Verification is ON.
A15: 6 | B15: monday.com trial ended | C15: P1 | D15: Trial lapsed ~Jun 24; 9 team invites pending (blocked by email anyway). | E15: Decide: pay for the plan, OR export boards + cancel
A16: 7 | B16: 8 scattered email identities | C16: P2 | D16: rspplowman@gmail + 7 others (noizy.ai, icloud, outlook, fishmusicinc x2, noizylab.ca, rspnoizy@gmail). | E16: Forward all → rspplowman@gmail.com as the single command inbox
A17: 8 | B17: GitHub account hardening | C17: P2 | D17: Many repeated sudo codes on rspplowman-cloud — lots of admin activity. | E17: Confirm 2FA + passkey + recovery codes saved on GitHub

Sheet Heaven Worker
A1: HEAVEN WORKER — the AI brain of the NOIZY EMPIRE
A2: Not a server — a self-running AI agent that orchestrates your media, your catalog, your brands, and your council. Built on Cloudflare's Agents SDK (live 2025). Deploys from RSPNOIZY/NOIZYLAB.
A4: 1 · THE BRAIN — how Heaven is built
A5: Component | B5: Cloudflare tech | C5: What it does for NoizyLab
A6: 👑 HEAVEN (master agent) | B6: Agents SDK on Workers (npm i agents) | C6: The orchestrator. Holds state, calls AI models, runs scheduled tasks, and directs all other agents — by voice (RSP_001) or chat.
A7: ⚡ CB01–CB05 (council) | B7: Durable Objects (free tier, own SQLite each) | C7: Your 5 Daily Council agents as real, persistent AI agents — each with its own memory. Heaven convenes them on schedule (11am EDT).
A8: 🧠 Memory / Knowledge | B8: AutoRAG + Vectorize over R2 | C8: Heaven READS your CANON, GOSPEL, BRAND_MAP & audio metadata. Ask it anything — it retrieves the answer from your own corpus. This is the GOSPEL made queryable.
A9: 🎵 Media + Catalog | B9: R2 (audio) + D1 (catalog DB) | C9: All your audio lives in R2; the catalog (Library/Samples/Brands) is a live D1 database Heaven queries instantly.
A10: 🏷️ Tagging engine | B10: Workers AI (edge models) | C10: Cloud tagging/embeddings when the M2 Ultra is off — names orphans, classifies by brand, 24/7.
A11: 🔌 HEAVEN-as-a-tool | B11: MCPAgent class (Agents SDK) | C11: Heaven exposes itself as an MCP server — so I (Claude) connect to it as a live tool and query your catalog, run your council, search your corpus DIRECTLY. This is 'do more, be smarter' made real.
A13: 2 · WHAT YOU CAN ASK HEAVEN (once it's live)
A14: 🗣️ "Heaven, find every dark cinematic NoizyBeast loop" → semantic search across your whole library (Vectorize) — not keywords, MEANING.
A15: 🗣️ "Heaven, convene the Daily Council" → wakes CB01–CB05, each with its own memory, reports back. The Gathering, automated.
A16: 🗣️ "Heaven, what does the CANON say about the NoizyKidz brand?" → reads your own GOSPEL/BRAND_MAP and answers (AutoRAG).
A17: ⚡ New audio lands in R2 → Heaven auto-names the orphan, tags it, routes it by BRAND_MAP, updates the catalog, keeps 3-2-1 — 24/7, even when the M2 sleeps.
A18: 📊 "Heaven, status of the empire" → live numbers from D1: files, brands, dupes, what needs attention.
A20: 3 · HOW IT GETS BUILT (one command to start)
A21: npm create cloudflare@latest agents-starter -- --template="cloudflare/agents-starter"
A22: ↑ That one line gives you a working AI agent + chat UI, ready to deploy to Workers. Then we rename it Heaven and wire in your R2 / D1 / Vectorize. I write the agent code with you — you don't.
A24: 4 · BUILD ORDER
A25: 1. Finish DNS/email (Fix Walkthrough) — domains live in Cloudflare first
A26: 2. PULL THE REPO — so I can read what's already in heaven/, schemas/, CANON before we build
... A32: 🔑 The whole design hinges on one read: PULL THE REPO. heaven/ already exists in RSPNOIZY/NOIZYLAB — you may have already started building this. Let me look before we write a single new line.

Sheet Cloudflare Worker
A1: CLOUDFLARE WORKER — the engine room of the NOIZY empire
A2: Serverless code that runs on Cloudflare's edge — no server to manage, generous free tier, deploys straight from your GitHub repo. This is the backbone for the Super IDE, noizy.ai, and your media cloud.
A4: 1 · THE CLOUDFLARE STACK — mapped to YOUR empire
A5: Cloudflare piece | B5: What it is | C5: What it does for NoizyLab
A6: Workers | B6: Serverless code at the edge (the 'Worker') | C6: ⭐ The Super IDE backend + API + automation brain. Runs your catalog logic, no server to rent.
A7: R2 Storage | B7: S3-compatible object storage, NO egress fees | C7: ⭐ YOUR MEDIA CLOUD. The audio/video offsite tier for 3-2-1. Cheaper than AWS (no download fees).
A8: D1 Database | B8: Serverless SQL database | C8: ⭐ The catalog database — Library, Samples, Brands, the whole index, live and queryable.
A9: Pages | B9: Static + dynamic website hosting | C9: Host noizy.ai, noizylab.ca, the Super IDE front-end — all your sites.
A10: Workers AI | B10: Run AI models at the edge | C10: Cloud tagging/naming when the M2 is off — a backup to LM Studio.
A11: Workers KV | B11: Fast key-value store | C11: Config, settings, fast lookups for the IDE.
A12: Durable Objects | B12: Stateful real-time coordination | C12: Could run THE DAILY COUNCIL — the 5 agents coordinating in real time.
A14: 2 · HOW IT DEPLOYS (no coding — it builds from your GitHub)
A15: Connect repo | B15: Cloudflare dash → Workers & Pages → Create → Import a Git repository → pick RSPNOIZY/NOIZYLAB. Every push to GitHub auto-builds & deploys.
A16: Auto-provision | B16: If the repo needs a database (D1), media store (R2), or cache (KV), Cloudflare creates and wires them for you automatically.
A17: One-click button | B17: A 'Deploy to Cloudflare' button can live in your repo README — one click clones + deploys the whole app.
A18: Safe previews | B18: Every change gets a preview URL before it goes live — test first, then ship. Nothing breaks the real site.
A20: 3 · THE BUILD ORDER
A21: 1. Finish the DNS/email fix first (Fix Walkthrough) — domains must be live in Cloudflare.
A22: 2. Cloudflare → Workers & Pages → Create → Import Git → RSPNOIZY/NOIZYLAB.
A23: 3. Provision R2 (your media cloud) + D1 (your catalog database).
A24: 4. Deploy the Worker (your API) — then every git push ships automatically.
A25: 5. Point noizy.ai at the Worker/Pages — the empire goes live.
A26: 6. Pull the repo here so I can read CANON / schemas / docs and tell you what's already built.
A28: ⭐ YOU ARE ALREADY HALFWAY: on May 28 you connected Cloudflare to your GitHub (rspplowman-cloud). The wiring exists — you just haven't deployed yet. Finish DNS → import the repo → your Super IDE has a home.

Sheet Fix Walkthrough
A1: FIX WALKTHROUGH — bring your email & team back online (steps 4-10)
A2: Exact Cloudflare click-path (pulled from live Cloudflare docs). Do these in order. Each fills a mailbox back to life. Mark Done as you go.
A4: STEP | B4: DO EXACTLY THIS | C4: Done?
A5: 4 · Turn ON Email Routing for noizylab.ca | B5: 1. Go to dash.cloudflare.com and log in. 2. Click your account, then click the domain noizylab.ca. 3. Left menu: Compute > Email Service > Email Routing. 4. Click 'Onboard Domain' and choose noizylab.ca. 5. Cloudflare shows the MX/SPF/DKIM records it will add — click 'Done'. (It adds them for you — THIS is the missing piece.) 6. Wait 5-15 minutes for it to go green. | C5: Not started
A6: 5 · Add & verify YOUR inbox (the destination) | B6: 1. Same place: Email Service > Email Routing > 'Destination Addresses'. 2. In the box, type: rspplowman@gmail.com and submit. 3. Cloudflare emails you a verification link — open it in Gmail, click 'Verify email address'. 4. Until this is verified, nothing forwards. This is the one-time key. | C6: Not started
A7: 6 · Create the 5 team addresses (noizylab.ca) | B7: For EACH of the 5 people, make one routing rule: 1. Email Routing > 'Routing Rules' tab > 'Create routing rule'. 2. Email pattern: type the name part only — lucy (then gabriel, shirl, engr_keith, pops). 3. Action: 'Send to an email'. 4. Destination: pick rspplowman@gmail.com (the verified one). 5. Save. Repeat for all 5. Result: lucy@noizylab.ca, gabriel@, shirl@, engr_keith@, pops@ all land in YOUR Gmail. | C7: Not started
A8: 7 · Repeat for fishmusicinc.com | B8: Same as steps 4 + 6, for fishmusicinc.com: 1. Email Routing > 'Onboard Domain' > choose fishmusicinc.com > Done. 2. Routing Rules > Create rule: pattern 'rp' > Send to email > rspplowman@gmail.com > Save. 3. Add another: pattern 'rsp' > same destination > Save. Result: rp@ and rsp@fishmusicinc.com forward to your Gmail. (Destination already verified in step 5 — reused.) | C8: Not started
A9: 8 · Fix gabriel@noizy.ai (different — Workspace) | B9: noizy.ai is Google Workspace (NOT Cloudflare routing), so its mailbox is made in Google: 1. Go to admin.google.com (sign in as rsp@noizy.ai). 2. Directory > Users > 'Add new user'. 3. Create gabriel @ noizy.ai (or, if Gabriel only needs forwarding, add it as an alias/group to your account). 4. This stops the 'address not found 550' bounce for gabriel@noizy.ai. | C9: Not started
A10: 9 · Test every address | B10: From a DIFFERENT account (e.g. rsplowman@icloud.com — NOT your Gmail), send a test email to each: lucy@noizylab.ca, gabriel@noizylab.ca, shirl@noizylab.ca, engr_keith@noizylab.ca, pops@noizylab.ca, rp@fishmusicinc.com, rsp@fishmusicinc.com, gabriel@noizy.ai. Each should arrive in your Gmail within minutes (check Spam too). Any that don't — re-check that domain's routing rule + that the destination is verified. | C10: Not started
A11: 10 · Re-send all the stuck invites | B11: Now that mail flows, reconnect the team: 1. monday.com > invite the 9 people again (their addresses now work). 2. Slack > invite the team + create channels (#empire, #daily-council, #fishmusic, #brands). 3. Re-send any GitHub/Jira/Atlassian invites. The Daily Council can finally assemble with everyone reachable. | C11: Not started
A13: WHEN ALL 7 ARE DONE → your empire's nervous system is back online. Every bounce stops, the team reconnects, and we move to pulling the repo + the first media scan.

Sheet Build Readiness
A1: BUILD READINESS — your M2 Ultra as the hub (no coding required)
A2: Plain-English roadmap to wire Slack, Discord & Microsoft to your machine. You don't write code — you connect, I guide. One step at a time.
A4: YOUR HUB — n8n (the brain that connects everything)
A5: What it is | B5: A free, drag-and-drop automation app that runs ON your M2 Ultra. No coding — you connect boxes (nodes) with lines. You already use it (your Command Inbox).
A6: Why it's perfect for you | B6: One place to wire Slack + Discord + Microsoft + your local LM Studio + your files. Your data never leaves your machine. It even has AI nodes that talk to your local 70B model.
A7: Start it (one line) | B7: docker run -it --rm --name n8n -p 5678:5678 -v ~/.n8n:/home/node/.n8n n8nio/n8n
A8: Then open | B8: http://localhost:5678 — that's your control panel. Build workflows by dragging nodes.
A10: INTEGRATION CHECKLIST
A11: Connect | B11: What it does for you | C11: How to connect (plain English) | D11: Status
A12: Slack | B12: Talk to your system from Slack; get alerts when scans finish, files move, or something needs you. | C12: Make a Slack app (api.slack.com → Create New App), copy the Bot Token (xoxb-…), paste into n8n's Slack node. ~10 min, no code. | D12: Not started
A13: Discord | B13: Same as Slack but for Discord — command + notifications in your server/community. | C13: Discord Developer Portal → create a bot → copy bot token → paste into n8n's Discord node. No bot coding. | D13: Not started
A14: Microsoft (Power Automate) | B14: Bridges to the Microsoft world — Excel, OneDrive, SharePoint, Outlook; can also trigger desktop flows on your Mac. | C14: In Power Automate, add the Slack/Excel connector (no-code), approve the app permission. Use it for anything Microsoft-side. | D14: Not started
A15: LM Studio (local AI) | B15: Your 70B brain does the naming, tagging & classifying — locally, free, private. | C15: In n8n add an AI node pointed at http://localhost:1234 (LM Studio's API). It calls your local model with no cloud cost. | D15: Not started
A16: Your Files (Desktop Commander) | B16: Lets the hub actually read /Volumes/Audio, hash, dedupe & move — the scan engine. | C16: Install Desktop Commander (Action Register ACT-003). n8n can also run shell steps to scan folders. | D16: Not started
A17: GitHub (your code) | B17: Carries your 2 years of code into the system — audited into the registry. | C17: Give me your repo names (owner/repo); I add + audit each. n8n can also auto-post commits to Slack/Discord. | D17: Not started
A19: READINESS | B19: =TEXT(COUNTIF(D12:D17,"Done")/6,"0%") -> 0% | C19: =REPT("█",COUNTIF(D12:D17,"Done"))&REPT("░",6-COUNTIF(D12:D17,"Done")) -> ░░░░░░
A21: DO THESE IN ORDER (each one is a win you can see):
A22: 1. Start n8n on the M2 Ultra (you already have it) — open localhost:5678.
A23: 2. Connect LM Studio (local AI) — free, instant, private. Your first win.
A24: 3. Install Desktop Commander — then run your FIRST real scan of /Volumes/Audio.
A25: 4. Connect Slack — so the system can talk to you & alert you.
A26: 5. Connect Discord — same, for your community/server.
A27: 6. Microsoft (Power Automate) + give me your GitHub repo names — I audit the code.
A29: You are never doing this alone. You connect; I guide every click and carry the work forward.

Sheet Setup To-Do
A1: SETUP TO-DO — LM Studio, Desktop Commander & all, step by step
A2: Do these in order. Each is one small action. Mark Status 'Done' and the bar fills. Nothing here needs coding — just copy, paste, click.
A3: # | B3: Task | C3: Do exactly this | D3: Why it matters | E3: Status
A4: A | B4: LM STUDIO — your local AI brain (start here, free win)
A5: 1 | B5: Open LM Studio | C5: Launch the LM Studio app on the M2 Ultra. | D5: It's the engine that names & tags your audio. | E5: Not started
A6: 2 | B6: Load a model | C6: Search tab → download Qwen2.5-72B-Instruct (MLX). Then click to load it. | D6: Your 192GB RAM runs it easily; this is the smarts. | E6: Not started
A7: 3 | B7: Turn GPU offload to MAX | C7: In the model load settings, set GPU offload to maximum (all layers). | D7: Uses the full chip = fast responses. | E7: Not started
A8: 4 | B8: Start the local server | C8: Developer tab → Start Server. Leave it on port 1234. | D8: Opens the door so n8n & tools can talk to it. | E8: Not started
A9: 5 | B9: Add a filesystem MCP in LM Studio | C9: Program → Edit MCP → add the filesystem server, point it at /Volumes/Audio. | D9: Lets the AI read your drive to scan + classify. | E9: Not started
A10: B | B10: DESKTOP COMMANDER — lets me read & move your files
A11: 6 | B11: Install Desktop Commander | C11: Open Terminal, paste: npx -y @wonderwhy-er/desktop-commander setup | D11: One command. Installs the file/scan agent. | E11: Not started
A12: 7 | B12: Restart Claude Desktop | C12: Fully quit and reopen Claude Desktop so it loads the new tool. | D12: Activates the connection. | E12: Not started
A13: 8 | B13: Point it at your audio drive | C13: When asked, allow the folder /Volumes/Audio (and 12RB, MAG4TB). | D13: Scopes it safely to only your audio. | E13: Not started
A14: 9 | B14: Test it | C14: In Claude Desktop ask: “list the files in /Volumes/Audio”. | D14: Proves the bridge to your drive is live. | E14: Not started
A15: C | B15: FIRST SCAN — the moment the catalog comes alive
A16: 10 | B16: Run the fast scan | C16: Copy the Method-A command from the Scan Commands tab into Terminal. | D16: Lists every file in seconds. | E16: Not started
A17: 11 | B17: Bring it to me | C17: Drag the audio_scan.csv into our chat (or paste into Scan Queue, cell B4). | D17: I load every file → brands, dupes, guards all light up. | E17: Not started
A18: D | B18: n8n HUB + ALERTS — Slack & Discord (optional, do after scan)
A19: 12 | B19: Start n8n | C19: Terminal: docker run -it --rm --name n8n -p 5678:5678 -v ~/.n8n:/home/node/.n8n n8nio/n8n → open localhost:5678 | D19: Your no-code automation hub. | E19: Not started
A20: 13 | B20: Connect Slack | C20: api.slack.com/apps → Create App → copy Bot Token (xoxb-) → paste into n8n Slack node. | D20: System messages you when jobs finish. | E20: Not started
A21: 14 | B21: Connect Discord | C21: Discord Developer Portal → New bot → copy token → paste into n8n Discord node. | D21: Same alerts, in your Discord. | E21: Not started
A22: E | B22: CLOUD + CODE — close the loop
A23: 15 | B23: Connect the right Google account | C23: + menu → Connectors → Google Drive/Gmail → sign in as rsplowman@gmail.com. | D23: Unlocks the ~250GB; I re-scan instantly. | E23: Not started
A24: 16 | B24: Give me your GitHub repo names | C24: Just type them to me, e.g. “noizyarmy/beast-engine”. | D24: I pull & audit your 2 years of code. | E24: Not started
A26: PROGRESS | B26: =TEXT(COUNTIF(E5:E24,"Done")/16,"0%") -> 0% | C26: =REPT("█",COUNTIF(E5:E24,"Done"))&REPT("░",16-COUNTIF(E5:E24,"Done")) -> ░░░░░░░░░░░░░░░░ | D26: =COUNTIF(E5:E24,"Done")&" of 16 done" -> 0 of 16 done

Sheet Connector Audit
A1: CONNECTOR AUDIT — what you built vs. what you use
A2: Live inventory of every MCP / integration wired into your Claude account, 2026-06-30.
A3: ANSWER: You've connected 36 services. Only ~4 used this session. ~20 connected but idle. 12 broken (need re-auth). → ~32 of 36 built and barely/never used.
A5: COUNT
A6: Total connectors built | B6: 36
A7: Connected & used (this session) | B7: 4
A8: Connected but IDLE (never used) | B8: 20
A9: FAILED / broken (re-auth needed) | B9: 12
A11: Connector | B11: Status | C11: Used? | D11: Use for NoizyArmy
A12: Google Drive | B12: Connected | C12: ✓ USED | D12: Cloud media + file scan
A13: Gmail | B13: Connected | C13: ✓ USED | D13: Email media scan
A14: Adobe for creativity | B14: Connected | C14: ✓ USED | D14: Creative Cloud asset scan
A15: Claude Code Remote | B15: Connected | C15: ✓ USED | D15: ⭐ YOUR CODE access (name a repo, I pull it)
A16: Slack | B16: Connected | C16: idle | D16: ⭐ Alerts hub (Build Readiness)
A17: Notion | B17: Connected | C17: idle | D17: ⭐ Ideation / docs carry-forward
A18: Supabase | B18: Connected | C18: idle | D18: ⭐ Database for catalog + Super IDE
A19: Zapier | B19: Connected | C19: idle | D19: Automation bridge (8000+ apps)
A20: Vercel | B20: Connected | C20: idle | D20: Host the Super IDE / web app
A21: Netlify | B21: Connected | C21: idle | D21: Host / deploy
A22: Cloudflare Developer Platform | B22: Connected | C22: idle | D22: Deploy / CDN / workers
... A47: Instrumentl | B47: FAILED | C47: broken | D47: Grants (low priority)

Sheet Brand Universe
A1: THE NOIZY EMPIRE — brand universe & deepest content locations
A2: Discovered by deep scan of Gmail + Drive (2026-06-30). The constellation, the people, the code, and where every piece lives.
A4: 1 · THE BRAND CONSTELLATION
A5: Brand / Entity | B5: What it is | C5: Evidence found
A6: NOIZY.AI | B6: Parent / AI brand | C6: Business profile (42 views/mo May 2026); noizy.ai domain
A7: NOIZYLAB (noizylab.ca) | B7: The lab / R&D + team domain | C7: Business profile; GitHub repo RSPNOIZY/NOIZYLAB; team emails @noizylab.ca
A8: NOIZYFISH / fishmusicinc | B8: Music arm | C8: fishmusicinc' module in canonical repo
A9: NOIZYVOX | B9: Vocals / voice | C9: Named brand (content pending scan)
A10: NOIZYKIDZ | B10: Kids / family content | C10: Named brand (content pending scan)
A11: DREAMCHAMBER | B11: Ideation / creative space | C11: Named brand (likely the council/agent space)
A12: THE GATHERING / DAILY COUNCIL | B12: The 5-agent operating ritual | C12: Calendar: 'NOIZY EMPIRE Morning Planning — five agents assemble, RSP_001 directs by voice'
A13: HEAVEN | B13: Project module | C13: heaven' module in canonical repo
A14: NOIZYANTHROPIC / NOIZYBEAST / METABEAST | B14: Original 3 house brands | C14: Catalogued in Brands tab
A16: 2 · DEEPEST CONTENT LOCATIONS
A17: Location | B17: What's there | C17: Reachable?
A18: GitHub: RSPNOIZY/NOIZYLAB | B18: CANONICAL repo — CANON, GOSPEL, BRAND_MAP, fishmusicinc, heaven, schemas, docs. Your doctrine + ideation. | C18: YES — I can pull it (say go)
A19: Google Calendar | B19: NOIZY EMPIRE Daily Council — 5-agent ritual, RSP_001 directs by voice | C19: Connector idle — activate
A20: Domains: noizy.ai + noizylab.ca | B20: Brand homes; mid-transfer GoDaddy → Cloudflare | C20: Cloudflare connector idle
A21: Gmail: rspplowman@gmail.com | B21: Empire command hub — all planning, team comms, vendor mail | C21: YES — scanned
A22: M2 Ultra + 250GB cloud | B22: The actual audio/video media | C22: Pending scan / connect
A24: 3 · THE PEOPLE (NOIZY EMPIRE)
A25: Robert S. Plowman — RSP_001 | B25: Founder; 'directs by voice'; rspplowman@gmail.com, rsp@noizy.ai
A26: Gabriel | B26: gabriel@noizy.ai (collaborator, BR-101)
A27: Lucy | B27: lucy@noizylab.ca (collaborator, BR-102)
A28: Keith (Engineer) | B28: engr_keith@noizylab.ca
A29: Pops | B29: pops@noizylab.ca
A30: Shirl | B30: shirl@noizylab.ca
A32: 4 · ADMIN ALERTS (real problems found)
A33: ⚠ noizylab.ca email is BROKEN | B33: ALL team emails (lucy, gabriel, keith, pops, shirl @noizylab.ca) BOUNCE — DNS/MX not set. Your team cannot receive mail. Likely caused by the GoDaddy→Cloudflare transfer leaving DNS unconfigured.
A34: ⚠ gabriel@noizy.ai bounces too | B34: Address not found' — mailbox not created on noizy.ai
A35: → FIX | B35: After Cloudflare transfer completes, set MX records + create mailboxes (Google Workspace). Then team email works.

Sheet People & Agents
A1: PEOPLE & AGENTS — the NOIZY Empire roster
A2: Every human, every agent, every identity — grouped, grepped, and mapped to where they live. Sourced from Gmail + Calendar + GitHub scan.
A4: 1 · ROBERT'S IDENTITIES (your own accounts — consolidate these)
A5: Identity | B5: Where / Role | C5: Status
A6: rspplowman@gmail.com | B6: Personal Gmail — empire command hub | C6: ✅ CONNECTED (this is what I scan)
A7: rsp@noizy.ai | B7: Workspace admin — Drive connector | C7: Connected (near-empty)
A8: rspnoizy@gmail.com | B8: Secondary Gmail | C8: Found in monday.com invites
A9: RSPNOIZY@outlook.com | B9: Microsoft identity (ties to MS Automate) | C9: Found — not connected
A10: rsplowman@icloud.com | B10: Apple/iCloud identity (M2 Ultra) | C10: Found — not connected
A11: rspnoizy (GitHub) | B11: GitHub owner — RSPNOIZY/NOIZYLAB repo | C11: ⭐ Reachable via add_repo
A12: RSP_001 | B12: Council voice ID — 'directs by voice' | C12: The Daily Council director
A14: 2 · THE HUMAN TEAM (noizylab.ca)
A15: Person | B15: Email | C15: Role / Brand | D15: Email Status
A16: Gabriel | B16: gabriel@noizylab.ca / gabriel@noizy.ai | C16: Sound design (BR-101) | D16: 🔴 BOUNCING
A17: Lucy | B17: lucy@noizylab.ca | C17: Vocals (BR-102) | D17: 🔴 BOUNCING
A18: Shirl | B18: shirl@noizylab.ca | C18: Role TBD (in BRAND_MAP) | D18: 🔴 BOUNCING
A19: Keith (Engineer) | B19: engr_keith@noizylab.ca | C19: Engineering | D19: 🔴 BOUNCING
A20: Pops | B20: pops@noizylab.ca | C20: Role TBD (in BRAND_MAP) | D20: 🔴 BOUNCING
A21: Alex Ward | B21: (email TBD) | C21: Role TBD — in RSPNOIZY/NOIZYLAB repo | D21: ⏳ pull repo to confirm
A23: 3 · THE COUNCIL — DREAMCHAMBER (the five agents)
A24: THE DAILY COUNCIL — the five agents assemble, RSP_001 directs by voice' — recurring 11am EDT weekday Google Meet. CB01–CB05 = the five agents.
A25: CB01 | B25: Council Agent 1 | C25: Role in CANON/BRAND_MAP — pull repo
A26: CB02 | B26: Council Agent 2 | C26: Role in CANON/BRAND_MAP — pull repo
A27: CB03 | B27: Council Agent 3 | C27: Role in CANON/BRAND_MAP — pull repo
A28: CB04 | B28: Council Agent 4 | C28: Role in CANON/BRAND_MAP — pull repo
A29: CB05 | B29: Council Agent 5 | C29: Role in CANON/BRAND_MAP — pull repo
A31: 4 · WHERE THE EMPIRE LIVES (platforms found)
A32: monday.com | B32: Work mgmt — 9 invites sent, team hasn't joined (bounced emails)
A33: Google Calendar | B33: THE DAILY COUNCIL — recurring 11am EDT, Google Meet
A34: GitHub RSPNOIZY/NOIZYLAB | B34: ⭐ Canonical repo — CANON, GOSPEL, BRAND_MAP, fishmusicinc, heaven, schemas, docs
A35: Slack + Jira/Atlassian | B35: Slack pending; Jira reactivated (user RSPNOIZY)
A37: 5 · ADMIN ALERTS & PENDING
A38: 🔴 ALL noizylab.ca emails BOUNCING — DNS/MX not set (GoDaddy→Cloudflare transfer). Team can't receive your mail. FIX: finish Cloudflare DNS + set MX + create mailboxes.
A39: ⏳ myFAMILY.ai — new brand/domain, not yet in comms; likely defined in BRAND_MAP (repo).
A40: ⏳ Alex Ward, CB01–CB05 roles, Heaven & DreamChamber details — all live in RSPNOIZY/NOIZYLAB. PULL THE REPO to populate.
A41: ⏳ You have 5+ email identities (gmail x2, noizy.ai, outlook, icloud) — consolidate to one command address.

Sheet Identity & Footprint
A1: IDENTITY & FOOTPRINT — every account, everywhere you exist online
A2: Deepest scan: Gmail trail + Slack + public web. Maps all identities, domains, platforms — and the one root issue breaking them.
A4: 1 · WHO YOU ARE (public record)
A5: Robert Stephen Plowman (R.S. Plowman / “Rob”) — Fish Music Inc., Ottawa ON. AWARD-WINNING composer & sound designer, 30+ yrs.
A6: Credits found | B6: Transformers, My Little Pony, Care Bears, Johnny Test, Ed Edd n Eddy, Dragon Tales, Bratz, He-Man, Strawberry Shortcake, Barbie films, Madeline, Noddy
A7: Public profiles | B7: facebook.com/fishmusicinc · linkedin.com/in/robplowman · YouTube 'Fish Music — Music & Sounds By R.S Plowman' · Canadian Animation Directory
A8: Business | B8: Fish Music Inc., 771 Eastbourne Ave, Ottawa ON K1K 0H8 · rp@fishmusicinc.com · original music + custom sound design for film/TV/animation/games
A9: Note (NOT you) | B9: Fish' (Derek Dick, Scottish singer) and Suzanne Ciani's 'Fish Music' are different people — excluded from your footprint.
A11: 2 · YOUR EMAIL IDENTITIES (8 found)
A12: Email | B12: Used For | C12: Status
A13: rspplowman@gmail.com | B13: PRIMARY command hub — Gmail connector, all account notifications land here | C13: ✅ WORKING
A14: rsp@noizy.ai | B14: Google Workspace (admin, sole user); Drive connector | C14: ✅ working
A15: rsplowman@icloud.com | B15: Apple ID; Google Payments profile 'RSP@ICLOUD'; old Notion login | C15: ✅ working
A16: rspnoizy@gmail.com | B16: Secondary Google; monday.com invitee | C16: ❓ unconfirmed
A17: RSPNOIZY@outlook.com | B17: Microsoft identity; monday.com invitee | C17: ❓ unconfirmed
A18: rp@fishmusicinc.com | B18: Legacy business email (public, on directories since the studio days) | C18: ❓ legacy
A19: rsp@fishmusicinc.com | B19: NEW Cloudflare email routing ('Day One 1996' test) — you tried to bring it live | C19: 🔴 BOUNCING
A20: rsp@noizylab.ca | B20: NoizyLab domain identity (and the whole team @noizylab.ca) | C20: 🔴 BOUNCING
A22: 3 · DOMAINS (all mid-transfer GoDaddy → Cloudflare)
A23: noizy.ai | B23: Parent brand; Google Workspace mail works here | C23: ⚠ transferring
A24: noizylab.ca | B24: The Lab + whole team (gabriel/lucy/shirl/keith/pops@) | C24: 🔴 email DOWN
A25: fishmusicinc.com | B25: Your 30-yr studio brand; new Cloudflare routing attempted | C25: 🔴 email DOWN
A26: myFAMILY.ai | B26: Mentioned in empire; details in RSPNOIZY/NOIZYLAB repo | C26: ❓ pending repo
A28: 4 · PLATFORMS & ACCOUNTS (where you operate)
A29: Azure DevOps | B29: Welcomed (rspplowman@gmail) — code/devops, likely early Super-IDE attempt | C29: idle
A30: Atlassian / Jira | B30: Account = 'Fish Music Inc.'; reactivated, user RSPNOIZY | C30: active
A31: monday.com | B31: Heavy use; 9 team invites pending; free trial ended ~Jun 24 | C31: ⚠ decide
A32: Notion | B32: Docs/wiki; login moved icloud → gmail | C32: 🔴 payment failing
A33: GitHub | B33: rspnoizy — repo RSPNOIZY/NOIZYLAB (CANON/GOSPEL/BRAND_MAP) | C33: ⭐ pull it
A34: YouTube / Facebook / LinkedIn | B34: Fish Music public presence — active artist footprint | C34: ✅ live
A35: Slack | B35: You (U0AEMKJCUPK) only — 0 channels, 0 team joined | C35: 🔴 empty
A36: Discord | B36: No connector + no email trail — nothing set up | C36: — none
A38: 5 · ROOT CAUSE — why so much is broken
A39: Every custom-domain email is DOWN — BOTH noizylab.ca AND fishmusicinc.com. The cause is one thing: on May 30 you authorized a full GoDaddy→Cloudflare transfer + account closure, but the Cloudflare DNS/MX email routing was never finished. No MX records = every mailbox bounces. That single gap cascades into stuck team invites, an empty Slack, and an isolated team.
A41: THE FIX (one move) | B41: In Cloudflare, for each domain (noizylab.ca, fishmusicinc.com): set MX records + enable Email Routing, create the mailboxes. That restores ALL team email → re-send monday/Slack invites → team reconnects.
A42: CONSOLIDATION | B42: Make rspplowman@gmail.com your single command identity (it already is in practice). Forward the other 7 into it so nothing is ever missed again.

Sheet DNS & Infrastructure
A1: DNS & INFRASTRUCTURE — the order of structure
A2: Every domain, nameserver, and mail route — reconstructed from your email trail. The root cause and the exact fix order.
A4: 1 · DOMAIN STRUCTURE
A5: Domain | B5: Registrar / Nameservers | C5: Mail (MX) Status | D5: Used For
A6: noizy.ai | B6: GoDaddy → Cloudflare (transferring) | C6: ✅ Google Workspace MX works (rsp@noizy.ai delivers) | D6: Parent brand, Workspace, GitHub org RSPNOIZY
A7: noizylab.ca | B7: GoDaddy → Cloudflare (transferring) | C7: 🔴 NO MX — 'DNS Error: mx lookup' — broken since ~Apr 7 | D7: Team mailboxes (lucy, gabriel, shirl, keith, pops)
A8: fishmusicinc.com | B8: GoDaddy → Cloudflare (transferring) | C8: 🔴 NO MX — Cloudflare Email Routing test bounced May 30 | D8: Business (rp@ / rsp@fishmusicinc.com), 30yr brand
A9: myFAMILY.ai | B9: Cloudflare (per repo) | C9: ❓ unknown — detail in RSPNOIZY/NOIZYLAB repo | D9: Family brand (in BRAND_MAP)
A11: 2 · THE TIMELINE (what happened, in order)
A12: ~Apr 7-9 | B12: noizylab.ca team emails already BOUNCING (lucy, keith, pops) — mail broken for months
A13: May 14-15 | B13: More bounces — every noizylab.ca address failing
A14: 46170 | B14: Cloudflare OAuth added to your GitHub (rspplowman-cloud) — Cloudflare ↔ GitHub linked
A15: 46172 | B15: You emailed GoDaddy: full transfer of ALL domains to Cloudflare + close account
A16: 46172 | B16: fishmusicinc.com email-routing test → BOUNCED ('the Azure Abyss')
A17: 46172 | B17: You emailed gabriel@noizy.ai: 'a plan to fix all the things RSP broke while rushing setup' — it bounced too
A18: Jun 2-3 | B18: Hard failures: 'DNS Error: DNS type mx lookup' = NO MX records exist
A20: 3 · THE FIX — ORDER OF OPERATIONS (do in sequence)
A21: Step 1 | B21: Confirm the GoDaddy→Cloudflare transfer COMPLETED — each domain shows 'Active' in your Cloudflare dashboard
A22: Step 2 | B22: Verify each domain's nameservers = Cloudflare (xxxx.ns.cloudflare.com)
A23: Step 3 | B23: noizy.ai → KEEP Google Workspace MX records (so rsp@noizy.ai keeps working); create the gabriel@noizy.ai mailbox in Workspace Admin
A24: Step 4 | B24: noizylab.ca → turn on Cloudflare Email Routing → add lucy / gabriel / shirl / engr_keith / pops → forward all to rspplowman@gmail.com
A25: Step 5 | B25: fishmusicinc.com → turn on Cloudflare Email Routing → rp@ and rsp@ → forward to rspplowman@gmail.com
A26: Step 6 | B26: Wait for DNS propagation (minutes–48h), send a test to each address, confirm it lands
A27: Step 7 | B27: Re-send the monday.com + Slack invites to the now-working addresses — team reconnects
A29: 4 · TOOLS THAT UPGRADE WHAT I CAN DO FOR YOU
A30: ✅ Cloudflare (connected) | B30: I can pull the exact Cloudflare click-path for Email Routing + MX setup on demand (docs search)
A31: ✅ GoDaddy (connected) | B31: I can check domain status / availability
A32: ⭐ ADD: Cloudflare API MCP | B32: A DNS-editing Cloudflare MCP would let me READ and SET your MX records directly — the single biggest upgrade for this fix
A33: ⭐ ADD: Filesystem / Desktop Commander | B33: Local file power for the media scan (see Setup To-Do)

Sheet Social & Admin Audit
A1: SOCIAL & ADMIN ACCOUNT AUDIT — scanned & conflict-resolved
A2: Every social + SaaS + admin account found across your Gmail, Slack & connectors — with conflicts flagged and the fix for each.
A4: 1 · SOCIAL ACCOUNTS
A5: Platform | B5: Account / Handle | C5: Status / Notes
A6: YouTube | B6: Fish Music — Music & Sounds By R.S Plowman | C6: ACTIVE — monthly analytics emails (NoizyFish brand)
A7: Instagram / X / TikTok | B7: (none found in scan) | C7: Not seen in Gmail — confirm if they exist under another handle
A8: Patreon / Threads / LinkedIn | B8: (none found in scan) | C8: No notifications found — likely not set up yet
A10: 2 · ADMIN / SAAS ACCOUNTS
A11: Service | B11: Account | C11: Status
A12: monday.com | B12: rspplowman@gmail.com | C12: ⚠ Free trial ENDED ~Jun 24 — decide keep/cancel; 9 team invites pending
A13: Notion | B13: rspplowman@gmail.com (Google + passkey) | C13: 🔴 PAYMENT FAILING — 4th charge declined, downgrade imminent. UPDATE CARD
A14: GitHub | B14: rspnoizy — repo RSPNOIZY/NOIZYLAB | C14: ACTIVE — canonical repo (CANON/GOSPEL/BRAND_MAP)
A15: Jira / Atlassian | B15: RSPNOIZY | C15: Reactivated (was on the broken-connector list)
A16: Google Workspace | B16: rsp@noizy.ai (admin) | C16: ACTIVE — sole user; near-empty Drive
A17: Google (personal) | B17: rspplowman@gmail.com | C17: ACTIVE — your command hub (Gmail connector)
A19: 3 · SLACK & DISCORD CHANNELS
A20: Slack | B20: Workspace connected (you = U0AEMKJCUPK) | C20: ⚠ 0 channels found — workspace not built out; team can't join (emails bounce)
A21: Discord | B21: No connector / no bridge to me | C21: Not reachable from here; no Discord emails found in scan
A23: 4 · CONFLICTS & RESOLUTIONS (AI-resolved)
A24: # | B24: Conflict | C24: Resolution | D24: Priority
A25: 1 | B25: ROOT CAUSE: Domains mid-transfer GoDaddy→Cloudflare (incomplete) | C25: Finish the Cloudflare transfer FIRST — it unblocks everything below | D25: P1
A26: 2 | B26: All noizylab.ca team emails bounce (Gabriel/Lucy/Shirl/Keith/Pops) | C26: After transfer: set MX records + create the 5 mailboxes → team gets mail | D26: P1
A27: 3 | B27: Notion payment failing (4th decline, downgrade imminent) | C27: Update card today — or export pages before downgrade wipes them | D27: P1
A28: 4 | B28: Team invites stuck (monday.com 9 pending + Slack empty) | C28: Same root cause — fix email (#1/#2), then re-send all invites | D28: P2
A29: 5 | B29: 5 email identities scattered (gmail/noizy.ai/outlook/icloud/rspnoizy) | C29: Pick ONE primary (rspplowman@gmail), forward the rest into it | D29: P2
A30: 6 | B30: monday.com trial ended — undecided | C30: Decide: pay to keep, or export boards + cancel | D30: P3
A31: 7 | B31: Slack workspace has no channels | C31: After email fix: create #empire #daily-council #fishmusic #brands, re-invite team | D31: P3
A33: 💡 THE ONE FIX: complete the GoDaddy→Cloudflare transfer. It cascades — email works, invites land, Slack fills, team reconnects. 4 of 7 conflicts resolve from that single action.

Sheet Drive Audit
A1: DRIVE AUDIT — complete contents of all drives
A2: Per-drive audit as of 2026-06-30. Cloud = live-scanned via connectors. Local = unreachable from this session (no filesystem bridge) — pending local-agent scan.
A3: VERDICT: 7 drives — 3 cloud AUDITED (~5KB, 0 media) | 1 cloud PENDING CONNECT (~250GB) | 3 local PENDING SCAN (~32TB). No media found in any reachable location.
A5: 1 · DRIVE SUMMARY
A6: Drive | B6: Type | C6: Reachable | D6: Scan Method | E6: Items | F6: Media | G6: Capacity | H6: Used | I6: Status
A7: Google Drive (Workspace) | B7: Cloud | C7: Yes | D7: Drive MCP | E7: 3 | F7: 0 | G7: 15 GB plan | H7: ~5 KB | I7: ✓ AUDITED
A8: Google Drive (personal) | B8: Cloud | C8: NOT connected | D8: (pending) | E8: ? | F8: ? | G8: ? | H8: ~250 GB | I8: ⏳ CONNECT rsplowman
A9: Gmail attachments | B9: Cloud | C9: Yes | D9: Gmail MCP | E9: 0 | F9: 0 | G9: — | H9: — | I9: ✓ AUDITED
A10: Adobe Creative Cloud | B10: Cloud | C10: Yes | D10: Adobe MCP | E10: 0 | F10: 0 | G10: — | H10: — | I10: ✓ AUDITED
A11: /Volumes/Audio | B11: Local | C11: No — sandbox | D11: needs local agent | E11: ? | F11: ? | G11: ~16 TB | H11: ? | I11: ⏳ PENDING SCAN
A12: 12RB | B12: Local | C12: No — sandbox | D12: needs local agent | E12: ? | F12: ? | G12: 12 TB | H12: ? | I12: ⏳ PENDING SCAN
A13: MAG4TB | B13: Local | C13: No — sandbox | D13: needs local agent | E13: ? | F13: ? | G13: 4 TB | H13: ? | I13: ⏳ PENDING SCAN
A15: 2 · CONTENTS DETAIL (every item found)
A16: Drive | B16: Item | C16: Type | D16: Size | E16: Created | F16: Modified
A17: GDrive (Workspace) | B17: Automating Command Inbox with n8n | C17: Google Sheet | D17: 1 KB | E17: 46131 | F17: 46131
A18: GDrive (Workspace) | B18: User_Download_03012026_165832 | C18: Google Sheet | D18: 3.9 KB | E18: 46025 | F18: 46032
A19: GDrive (Workspace) | B19: Google Admin Downloads | C19: Folder | D19: — | E19: 46025 | F19: 46025
A20: Gmail / Adobe CC | B20: (no items — scanned, empty of media) | C20: — | D20: — | E20: — | F20: —
A21: GDrive (personal) | B21: — awaiting connect (rsplowman@gmail.com) — | C21: ? | D21: ~250 GB | E21: — | F21: —
A22: /Volumes/Audio | B22: — awaiting local scan (Method-A / Desktop Commander) — | C22: ? | D22: ~16 TB | E22: — | F22: —
A23: 12RB | B23: — awaiting local scan — | C23: ? | D23: 12 TB | E23: — | F23: —
A24: MAG4TB | B24: — awaiting local scan — | C24: ? | D24: 4 TB | E24: — | F24: —

Sheet User & Email Audit
A1: USER & EMAIL AUDIT — deepest admin scan
A2: Source: Google Workspace admin export (User_Download), read + decoded via Drive connector. Max-depth enumeration of all users & email accounts.
